Traceback (most recent call last):
  File "../pretrained_main_subset_random_choosen_experiment.py", line 612, in <module>
    main()
  File "../pretrained_main_subset_random_choosen_experiment.py", line 129, in main
    mp.spawn(main_worker, nprocs=ngpus_per_node, args=(ngpus_per_node, args))
  File "/home/junzhin/anaconda3/lib/python3.7/site-packages/torch/multiprocessing/spawn.py", line 230, in spawn
    return start_processes(fn, args, nprocs, join, daemon, start_method='spawn')
  File "/home/junzhin/anaconda3/lib/python3.7/site-packages/torch/multiprocessing/spawn.py", line 188, in start_processes
    while not context.join():
  File "/home/junzhin/anaconda3/lib/python3.7/site-packages/torch/multiprocessing/spawn.py", line 150, in join
    raise ProcessRaisedException(msg, error_index, failed_process.pid)
torch.multiprocessing.spawn.ProcessRaisedException: 

-- Process 1 terminated with the following error:
Traceback (most recent call last):
  File "/home/junzhin/anaconda3/lib/python3.7/site-packages/torch/utils/data/dataloader.py", line 990, in _try_get_data
    data = self._data_queue.get(timeout=timeout)
  File "/home/junzhin/anaconda3/lib/python3.7/queue.py", line 179, in get
    self.not_empty.wait(remaining)
  File "/home/junzhin/anaconda3/lib/python3.7/threading.py", line 300, in wait
    gotit = waiter.acquire(True, timeout)
  File "/home/junzhin/anaconda3/lib/python3.7/site-packages/torch/utils/data/_utils/signal_handling.py", line 66, in handler
    _error_if_any_worker_fails()
RuntimeError: DataLoader worker (pid 31782) is killed by signal: Killed. 

The above exception was the direct cause of the following exception:

Traceback (most recent call last):
  File "/home/junzhin/anaconda3/lib/python3.7/site-packages/torch/multiprocessing/spawn.py", line 59, in _wrap
    fn(i, *args)
  File "/home/junzhin/Project/Summer_project/code/version1.0/pretrained_main_subset_random_choosen_experiment.py", line 359, in main_worker
    train(train_loader, model, criterion, optimizer, epoch, args, epoch)
  File "/home/junzhin/Project/Summer_project/code/version1.0/pretrained_main_subset_random_choosen_experiment.py", line 407, in train
    for i, (images, target) in enumerate(train_loader):
  File "/home/junzhin/anaconda3/lib/python3.7/site-packages/torch/utils/data/dataloader.py", line 521, in __next__
    data = self._next_data()
  File "/home/junzhin/anaconda3/lib/python3.7/site-packages/torch/utils/data/dataloader.py", line 1186, in _next_data
    idx, data = self._get_data()
  File "/home/junzhin/anaconda3/lib/python3.7/site-packages/torch/utils/data/dataloader.py", line 1142, in _get_data
    success, data = self._try_get_data()
  File "/home/junzhin/anaconda3/lib/python3.7/site-packages/torch/utils/data/dataloader.py", line 1003, in _try_get_data
    raise RuntimeError('DataLoader worker (pid(s) {}) exited unexpectedly'.format(pids_str)) from e
RuntimeError: DataLoader worker (pid(s) 31782) exited unexpectedly

slurmstepd: error: Detected 1 oom-kill event(s) in StepId=32818921.batch cgroup. Some of your processes may have been killed by the cgroup out-of-memory handler.
