Namespace(arch='alexnet', batch_size=512, center_crop=False, checkmodel_logsave=False, data='Office31', data_processing='ours', epochs=100, iters_per_epoch=1000, local=False, local_pretrained_path='', log='/home/junzhin/Project/Summer_project/code/version2.0/training_results/Alex_pretrained/D_A', lr=0.0001, lr_decay=0.75, lr_gamma=0.0003, momentum=0.9, per_class_eval=True, phase='train', pretrained=True, print_freq=100, root='/home/junzhin/Project/Summer_project/code/version2.0/data/office31', seed=None, source='D', target='A', wd=0.0005, workers=8)
=> using pre-trained model 'alexnet'
Traceback (most recent call last):
  File "/home/junzhin/Project/Summer_project/code/version2.0/common/utils/data.py", line 12, in __next__
    data = next(self.iter)
  File "/home/junzhin/anaconda3/lib/python3.7/site-packages/torch/utils/data/dataloader.py", line 521, in __next__
    data = self._next_data()
  File "/home/junzhin/anaconda3/lib/python3.7/site-packages/torch/utils/data/dataloader.py", line 1176, in _next_data
    raise StopIteration
StopIteration

During handling of the above exception, another exception occurred:

Traceback (most recent call last):
  File "../../../source_only.py", line 377, in <module>
    main(args)
  File "../../../source_only.py", line 143, in main
    lr_scheduler, epoch, args)
  File "../../../source_only.py", line 194, in train
    x_s, labels_s = next(train_source_iter)
  File "/home/junzhin/Project/Summer_project/code/version2.0/common/utils/data.py", line 15, in __next__
    data = next(self.iter)
  File "/home/junzhin/anaconda3/lib/python3.7/site-packages/torch/utils/data/dataloader.py", line 521, in __next__
    data = self._next_data()
  File "/home/junzhin/anaconda3/lib/python3.7/site-packages/torch/utils/data/dataloader.py", line 1176, in _next_data
    raise StopIteration
StopIteration
