Traceback (most recent call last):
  File "pretrained_main.py", line 484, in <module>
    main()
  File "pretrained_main.py", line 117, in main
    mp.spawn(main_worker, nprocs=ngpus_per_node, args=(ngpus_per_node, args))
  File "/home/junzhin/anaconda3/lib/python3.7/site-packages/torch/multiprocessing/spawn.py", line 230, in spawn
    return start_processes(fn, args, nprocs, join, daemon, start_method='spawn')
  File "/home/junzhin/anaconda3/lib/python3.7/site-packages/torch/multiprocessing/spawn.py", line 188, in start_processes
    while not context.join():
  File "/home/junzhin/anaconda3/lib/python3.7/site-packages/torch/multiprocessing/spawn.py", line 150, in join
    raise ProcessRaisedException(msg, error_index, failed_process.pid)
torch.multiprocessing.spawn.ProcessRaisedException: 

-- Process 1 terminated with the following error:
Traceback (most recent call last):
  File "/home/junzhin/anaconda3/lib/python3.7/site-packages/torch/multiprocessing/spawn.py", line 59, in _wrap
    fn(i, *args)
  File "/home/junzhin/Project/Summer_project/code/version1.0/pretrained_main.py", line 138, in main_worker
    world_size=args.world_size, rank=args.rank)
  File "/home/junzhin/anaconda3/lib/python3.7/site-packages/torch/distributed/distributed_c10d.py", line 608, in init_process_group
    _store_based_barrier(rank, store, timeout)
  File "/home/junzhin/anaconda3/lib/python3.7/site-packages/torch/distributed/distributed_c10d.py", line 247, in _store_based_barrier
    rank, store_key, world_size, worker_count, timeout
RuntimeError: Timed out initializing process group in store based barrier on rank: 1, for key: store_based_barrier_key:1 (world_size=8, worker_count=3, timeout=0:30:00)

Traceback (most recent call last):
  File "pretrained_main.py", line 484, in <module>
    main()
  File "pretrained_main.py", line 117, in main
    mp.spawn(main_worker, nprocs=ngpus_per_node, args=(ngpus_per_node, args))
  File "/home/junzhin/anaconda3/lib/python3.7/site-packages/torch/multiprocessing/spawn.py", line 230, in spawn
    return start_processes(fn, args, nprocs, join, daemon, start_method='spawn')
  File "/home/junzhin/anaconda3/lib/python3.7/site-packages/torch/multiprocessing/spawn.py", line 188, in start_processes
    while not context.join():
  File "/home/junzhin/anaconda3/lib/python3.7/site-packages/torch/multiprocessing/spawn.py", line 150, in join
    raise ProcessRaisedException(msg, error_index, failed_process.pid)
torch.multiprocessing.spawn.ProcessRaisedException: 

-- Process 1 terminated with the following error:
Traceback (most recent call last):
  File "/home/junzhin/anaconda3/lib/python3.7/site-packages/torch/multiprocessing/spawn.py", line 59, in _wrap
    fn(i, *args)
  File "/home/junzhin/Project/Summer_project/code/version1.0/pretrained_main.py", line 138, in main_worker
    world_size=args.world_size, rank=args.rank)
  File "/home/junzhin/anaconda3/lib/python3.7/site-packages/torch/distributed/distributed_c10d.py", line 576, in init_process_group
    store, rank, world_size = next(rendezvous_iterator)
  File "/home/junzhin/anaconda3/lib/python3.7/site-packages/torch/distributed/rendezvous.py", line 183, in _tcp_rendezvous_handler
    store = _create_c10d_store(result.hostname, result.port, rank, world_size, timeout)
  File "/home/junzhin/anaconda3/lib/python3.7/site-packages/torch/distributed/rendezvous.py", line 158, in _create_c10d_store
    hostname, port, world_size, start_daemon, timeout, multi_tenant=True
RuntimeError: connect() timed out. Original timeout was 1800000 ms.

