Namespace(arch='resnet18', batch_size=256, center_crop=False, checkmodel_logsave=False, data='Office31', data_processing='ours', epochs=30, iters_per_epoch=500, local=True, local_pretrained_path='/home/junzhin/Project/Summer_project/code/version1.0/old_model_results/Resnet18_office31masked2_newmodel_best.pth.tar', log='/home/junzhin/Project/Summer_project/code/version2.0/training_results/baseline_old/Resnet18_office31masked2/D_A', lr=0.001, lr_decay=0.75, lr_gamma=0.0003, momentum=0.9, per_class_eval=False, phase='train', pretrained=True, print_freq=100, root='/home/junzhin/Project/Summer_project/code/version2.0/data/office31', seed=None, source='D', target='A', wd=0.0005, workers=4)
=> using pre-trained model 'resnet18'
Epoch: [0][  0/500]	Time 6.063 (6.063)	Data 3.680 (3.680)	Loss 3.57 (3.57)	Cls Acc 3.1 (3.1)
Epoch: [0][100/500]	Time 6.103 (6.083)	Data 5.970 (5.927)	Loss 3.06 (3.21)	Cls Acc 16.8 (12.7)
Epoch: [0][200/500]	Time 6.126 (6.081)	Data 5.991 (5.935)	Loss 2.88 (3.08)	Cls Acc 23.8 (17.0)
Epoch: [0][300/500]	Time 6.074 (6.080)	Data 5.941 (5.938)	Loss 2.67 (2.98)	Cls Acc 32.8 (20.3)
Epoch: [0][400/500]	Time 6.125 (6.078)	Data 5.991 (5.938)	Loss 2.52 (2.88)	Cls Acc 34.0 (23.3)
Test: [ 0/12]	Time  1.701 ( 1.701)	Loss 5.6154e+00 (5.6154e+00)	Acc@1   0.00 (  0.00)	Acc@5  12.11 ( 12.11)
 * Acc@1 3.692 Acc@5 16.436
acc1 = 3.7, best_acc1 = 3.7
Epoch: [1][  0/500]	Time 6.079 (6.079)	Data 5.941 (5.941)	Loss 2.33 (2.33)	Cls Acc 38.7 (38.7)
Epoch: [1][100/500]	Time 6.102 (6.071)	Data 5.962 (5.937)	Loss 2.17 (2.24)	Cls Acc 43.4 (41.5)
Traceback (most recent call last):
  File "/home/junzhin/Project/Summer_project/code/version2.0/common/utils/data.py", line 12, in __next__
  File "/home/junzhin/anaconda3/lib/python3.7/site-packages/torch/utils/data/dataloader.py", line 521, in __next__
    data = self._next_data()
  File "/home/junzhin/anaconda3/lib/python3.7/site-packages/torch/utils/data/dataloader.py", line 1176, in _next_data
    raise StopIteration
StopIteration

During handling of the above exception, another exception occurred:

Traceback (most recent call last):
  File "../../../../source_only.py", line 377, in <module>
    main(args)
  File "../../../../source_only.py", line 143, in main
    lr_scheduler, epoch, args)
  File "../../../../source_only.py", line 194, in train
    x_s, labels_s = next(train_source_iter)
  File "/home/junzhin/Project/Summer_project/code/version2.0/common/utils/data.py", line 15, in __next__
  File "/home/junzhin/anaconda3/lib/python3.7/site-packages/torch/utils/data/dataloader.py", line 521, in __next__
    data = self._next_data()
  File "/home/junzhin/anaconda3/lib/python3.7/site-packages/torch/utils/data/dataloader.py", line 1203, in _next_data
    return self._process_data(data)
  File "/home/junzhin/anaconda3/lib/python3.7/site-packages/torch/utils/data/dataloader.py", line 1229, in _process_data
    data.reraise()
  File "/home/junzhin/anaconda3/lib/python3.7/site-packages/torch/_utils.py", line 434, in reraise
    raise exception
FileNotFoundError: Caught FileNotFoundError in DataLoader worker process 0.
Original Traceback (most recent call last):
  File "/home/junzhin/Project/Summer_project/code/version2.0/common/utils/data.py", line 12, in __next__
  File "/home/junzhin/anaconda3/lib/python3.7/site-packages/torch/utils/data/dataloader.py", line 521, in __next__
    data = self._next_data()
  File "/home/junzhin/anaconda3/lib/python3.7/site-packages/torch/utils/data/dataloader.py", line 1176, in _next_data
    raise StopIteration
StopIteration

During handling of the above exception, another exception occurred:

Traceback (most recent call last):
  File "/home/junzhin/anaconda3/lib/python3.7/site-packages/torch/utils/data/_utils/worker.py", line 287, in _worker_loop
    data = fetcher.fetch(index)
  File "/home/junzhin/anaconda3/lib/python3.7/site-packages/torch/utils/data/_utils/fetch.py", line 49, in fetch
    data = [self.dataset[idx] for idx in possibly_batched_index]
  File "/home/junzhin/anaconda3/lib/python3.7/site-packages/torch/utils/data/_utils/fetch.py", line 49, in <listcomp>
    data = [self.dataset[idx] for idx in possibly_batched_index]
  File "/home/junzhin/Project/Summer_project/code/version2.0/common/vision/datasets/imagelist.py", line 46, in __getitem__
  File "/home/junzhin/anaconda3/lib/python3.7/site-packages/torchvision/datasets/folder.py", line 269, in default_loader
    return pil_loader(path)
  File "/home/junzhin/anaconda3/lib/python3.7/site-packages/torchvision/datasets/folder.py", line 249, in pil_loader
    with open(path, 'rb') as f:
FileNotFoundError: [Errno 2] No such file or directory: '/home/junzhin/Project/Summer_project/code/version2.0/data/office31/dslr/images/stapler/frame_0008.jpg'

