Namespace(arch='alexnet', batch_size=256, center_crop=False, checkmodel_logsave=False, data='Office31', data_processing='ours', epochs=30, iters_per_epoch=500, local=True, local_pretrained_path='/home/junzhin/Project/Summer_project/code/version1.0/old_model_results/ALEX_office31masked2_newmodel_best.pth.tar', log='/home/junzhin/Project/Summer_project/code/version2.0/training_results/baseline_old/ALEX_office31masked2/D_A', lr=0.001, lr_decay=0.75, lr_gamma=0.0003, momentum=0.9, per_class_eval=False, phase='train', pretrained=True, print_freq=100, root='/home/junzhin/Project/Summer_project/code/version2.0/data/office31', seed=None, source='D', target='A', wd=0.0005, workers=4)
=> using pre-trained model 'alexnet'
Loading the local alexnet pretrained model weights!
Epoch: [0][  0/500]	Time 2.495 (2.495)	Data 1.277 (1.277)	Loss 3.44 (3.44)	Cls Acc 3.9 (3.9)
Epoch: [0][100/500]	Time 6.016 (5.991)	Data 5.981 (5.946)	Loss 3.43 (3.43)	Cls Acc 5.9 (4.3)
Epoch: [0][200/500]	Time 6.038 (6.004)	Data 6.005 (5.965)	Loss 3.43 (3.43)	Cls Acc 4.3 (4.8)
Epoch: [0][300/500]	Time 6.037 (6.008)	Data 6.005 (5.972)	Loss 3.42 (3.43)	Cls Acc 7.8 (5.3)
Epoch: [0][400/500]	Time 6.030 (6.012)	Data 5.998 (5.976)	Loss 3.41 (3.43)	Cls Acc 6.2 (5.5)
Test: [ 0/12]	Time  1.628 ( 1.628)	Loss 3.4820e+00 (3.4820e+00)	Acc@1   0.00 (  0.00)	Acc@5   0.00 (  0.00)
 * Acc@1 3.869 Acc@5 17.430
acc1 = 3.9, best_acc1 = 3.9
Epoch: [1][  0/500]	Time 6.029 (6.029)	Data 5.997 (5.997)	Loss 3.41 (3.41)	Cls Acc 6.2 (6.2)
Epoch: [1][100/500]	Time 5.985 (6.004)	Data 5.952 (5.972)	Loss 3.40 (3.40)	Cls Acc 6.6 (6.3)
Epoch: [1][200/500]	Time 6.015 (6.003)	Data 5.983 (5.971)	Loss 3.38 (3.40)	Cls Acc 7.0 (6.3)
Epoch: [1][300/500]	Time 5.997 (6.004)	Data 5.965 (5.971)	Loss 3.39 (3.40)	Cls Acc 7.0 (6.6)
Epoch: [1][400/500]	Time 6.047 (6.004)	Data 6.015 (5.971)	Loss 3.38 (3.39)	Cls Acc 7.4 (7.2)
Traceback (most recent call last):
  File "/home/junzhin/Project/Summer_project/code/version2.0/common/utils/data.py", line 12, in __next__
  File "/home/junzhin/anaconda3/lib/python3.7/site-packages/torch/utils/data/dataloader.py", line 521, in __next__
    data = self._next_data()
  File "/home/junzhin/anaconda3/lib/python3.7/site-packages/torch/utils/data/dataloader.py", line 1176, in _next_data
    raise StopIteration
StopIteration

During handling of the above exception, another exception occurred:

Traceback (most recent call last):
  File "../../../../source_only.py", line 377, in <module>
    main(args)
  File "../../../../source_only.py", line 143, in main
    lr_scheduler, epoch, args)
  File "../../../../source_only.py", line 194, in train
    x_s, labels_s = next(train_source_iter)
  File "/home/junzhin/Project/Summer_project/code/version2.0/common/utils/data.py", line 15, in __next__
  File "/home/junzhin/anaconda3/lib/python3.7/site-packages/torch/utils/data/dataloader.py", line 521, in __next__
    data = self._next_data()
  File "/home/junzhin/anaconda3/lib/python3.7/site-packages/torch/utils/data/dataloader.py", line 1203, in _next_data
    return self._process_data(data)
  File "/home/junzhin/anaconda3/lib/python3.7/site-packages/torch/utils/data/dataloader.py", line 1229, in _process_data
    data.reraise()
  File "/home/junzhin/anaconda3/lib/python3.7/site-packages/torch/_utils.py", line 434, in reraise
    raise exception
FileNotFoundError: Caught FileNotFoundError in DataLoader worker process 0.
Original Traceback (most recent call last):
  File "/home/junzhin/Project/Summer_project/code/version2.0/common/utils/data.py", line 12, in __next__
  File "/home/junzhin/anaconda3/lib/python3.7/site-packages/torch/utils/data/dataloader.py", line 521, in __next__
    data = self._next_data()
  File "/home/junzhin/anaconda3/lib/python3.7/site-packages/torch/utils/data/dataloader.py", line 1176, in _next_data
    raise StopIteration
StopIteration

During handling of the above exception, another exception occurred:

Traceback (most recent call last):
  File "/home/junzhin/anaconda3/lib/python3.7/site-packages/torch/utils/data/_utils/worker.py", line 287, in _worker_loop
    data = fetcher.fetch(index)
  File "/home/junzhin/anaconda3/lib/python3.7/site-packages/torch/utils/data/_utils/fetch.py", line 49, in fetch
    data = [self.dataset[idx] for idx in possibly_batched_index]
  File "/home/junzhin/anaconda3/lib/python3.7/site-packages/torch/utils/data/_utils/fetch.py", line 49, in <listcomp>
    data = [self.dataset[idx] for idx in possibly_batched_index]
  File "/home/junzhin/Project/Summer_project/code/version2.0/common/vision/datasets/imagelist.py", line 46, in __getitem__
  File "/home/junzhin/anaconda3/lib/python3.7/site-packages/torchvision/datasets/folder.py", line 269, in default_loader
    return pil_loader(path)
  File "/home/junzhin/anaconda3/lib/python3.7/site-packages/torchvision/datasets/folder.py", line 249, in pil_loader
    with open(path, 'rb') as f:
FileNotFoundError: [Errno 2] No such file or directory: '/home/junzhin/Project/Summer_project/code/version2.0/data/office31/dslr/images/stapler/frame_0017.jpg'

